2019-11-20 01:31:25:     Reconnected successfully!
2019-11-20 01:31:28:     Game type = "Red bonus tile" : True, "Open tanyao" : True, "Game  length" : tonnansen
2019-11-20 01:31:29:     Reconnected. Resuming game state...
2019-11-20 01:31:31:     --------------------------------------------------
2019-11-20 01:31:31:     Players: [weavile - 4¼‰ - 24000, Naruhodo - ËÄ¶Î - 24800, norizu - ËÄ¶Î - 32100, ÃÖÑå - ³õ¶Î - 19100]
2019-11-20 01:31:31:     Dealer: weavile - 4¼‰ - 24000
2019-11-20 01:31:31: Unexpected exception
Traceback (most recent call last):
  File "C:\Users\j4903\Documents\MahjongAI\main.py", line 17, in connect_and_play
    return client.start_game()
  File "C:\Users\j4903\Documents\MahjongAI\client\tenhou_client.py", line 123, in start_game
    '<REINIT' in msg and self._handle_reconnection_msg(msg)
  File "C:\Users\j4903\Documents\MahjongAI\client\tenhou_client.py", line 282, in _handle_reconnection_msg
    self._handle_initial_msg(msg)
  File "C:\Users\j4903\Documents\MahjongAI\client\tenhou_client.py", line 340, in _handle_initial_msg
    self._log('    Player wind: {}'.format(Tile.tile_graph_dict[self.game_table.bot.player_wind]))
  File "C:\Users\j4903\Documents\MahjongAI\client\mahjong_player.py", line 64, in player_wind
    if self.seat >= self.dealer_seat:
AttributeError: 'MahjongAgent' object has no attribute 'seat'
2019-11-20 01:31:31: End the game...
2019-11-20 01:31:31:     Game was ended unexpected
2019-11-20 01:31:31: 
