2019-02-07 11:38:49:     Reconnected successfully!
2019-02-07 11:38:50:     Game type = "Red bonus tile" : True, "Open tanyao" : True, "Game  length" : tonpusen
2019-02-07 11:38:50:     Reconnected. Resuming game state...
2019-02-07 11:38:54:     --------------------------------------------------
2019-02-07 11:38:54:  
2019-02-07 11:38:56:     [Player 3] draws a tile...
2019-02-07 11:38:57: 
2019-02-07 11:39:00: 
2019-02-07 11:39:00:     Remaining tiles: 17
2019-02-07 11:39:00:     --------------------------------------------------
2019-02-07 11:39:00: 
2019-02-07 11:39:01:     [Player 1] draws a tile...
2019-02-07 11:39:09:     [Player 2] draws a tile...
2019-02-07 11:39:21: 
2019-02-07 11:39:22:     [Player 1] draws a tile...
2019-02-07 11:39:24:     [Player 2] draws a tile...
2019-02-07 11:39:26:     [Player 3] draws a tile...
2019-02-07 11:39:30:     --------------------------------------------------
2019-02-07 11:39:30: 
2019-02-07 11:39:30:     <AGARI ba="0,0" hai="10,15,18,22,27,28,49,55,56,59,60,64,88,91" machi="49" ten="30,8000,1" yaku="7,1,8,1,52,2,54,1" doraHai="86" who="2" fromWho="3" sc="263,0,250,0,237,80,250,-80" />
2019-02-07 11:39:30: Unexpected exception
Traceback (most recent call last):
  File "c:\Users\j4903\Documents\MahjongAI\main.py", line 17, in connect_and_play
    return client.start_game()
  File "c:\Users\j4903\Documents\MahjongAI\client\tenhou_client.py", line 146, in start_game
    '<AGARI' in msg and self._handle_round_end(msg)
  File "c:\Users\j4903\Documents\MahjongAI\client\tenhou_client.py", line 404, in _handle_round_end
    self._round_end_info_to_file(res_str)
  File "c:\Users\j4903\Documents\MahjongAI\client\tenhou_client.py", line 748, in _round_end_info_to_file
    self.logger_obj.add_round_end_result(msg)
  File "c:\Users\j4903\Documents\MahjongAI\logger\logger_handler.py", line 57, in add_round_end_result
    open(self.scores_path, 'a').write(msg)
  File "C:\Users\j4903\AppData\Local\Programs\Python\Python37-32\lib\encodings\cp1252.py", line 19, in encode
    return codecs.charmap_encode(input,self.errors,encoding_table)[0]
UnicodeEncodeError: 'charmap' codec can't encode character '\U0001f01c' in position 81: character maps to <undefined>
2019-02-07 11:39:30: End the game...
2019-02-07 11:39:30:     Game was ended unexpected
2019-02-07 11:39:30: 
