2019-02-07 14:31:30:     Reconnected successfully!
2019-02-07 14:31:32:     Game type = "Red bonus tile" : True, "Open tanyao" : True, "Game  length" : tonnansen
2019-02-07 14:31:32:     Reconnected. Resuming game state...
2019-02-07 14:31:36:     --------------------------------------------------
2019-02-07 14:31:36:  
2019-02-07 14:31:38: 
2019-02-07 14:31:41: 
2019-02-07 14:31:41:     Remaining tiles: 15
2019-02-07 14:31:41:     --------------------------------------------------
2019-02-07 14:31:41: 
2019-02-07 14:31:42:     [Player 1] draws a tile...
2019-02-07 14:31:45:     [Player 2] draws a tile...
2019-02-07 14:31:51:     [Player 3] draws a tile...
2019-02-07 14:31:55: 
2019-02-07 14:31:57: 
2019-02-07 14:31:57:     Remaining tiles: 11
2019-02-07 14:31:57:     --------------------------------------------------
2019-02-07 14:31:57: 
2019-02-07 14:31:58:     [Player 1] draws a tile...
2019-02-07 14:31:59:     [Player 2] draws a tile...
2019-02-07 14:32:01:     --------------------------------------------------
2019-02-07 14:32:01: 
2019-02-07 14:32:01:     <AGARI ba="0,1" hai="72,75,76,77,79,81,85,91,92,99,100" m="40458" machi="79" ten="30,8000,1" yaku="35,5" doraHai="33" who="2" fromWho="2" sc="86,-20,263,-20,319,90,322,-40" />
2019-02-07 14:32:01: Unexpected exception
Traceback (most recent call last):
  File "C:\Users\j4903\Documents\MahjongAI\main.py", line 17, in connect_and_play
    return client.start_game()
  File "C:\Users\j4903\Documents\MahjongAI\client\tenhou_client.py", line 146, in start_game
    '<AGARI' in msg and self._handle_round_end(msg)
  File "C:\Users\j4903\Documents\MahjongAI\client\tenhou_client.py", line 404, in _handle_round_end
    self._round_end_info_to_file(res_str)
  File "C:\Users\j4903\Documents\MahjongAI\client\tenhou_client.py", line 748, in _round_end_info_to_file
    self.logger_obj.add_round_end_result(msg)
  File "C:\Users\j4903\Documents\MahjongAI\logger\logger_handler.py", line 57, in add_round_end_result
    open(self.scores_path, 'a').write(msg)
  File "C:\Users\j4903\AppData\Local\Programs\Python\Python37-32\lib\encodings\cp1252.py", line 19, in encode
    return codecs.charmap_encode(input,self.errors,encoding_table)[0]
UnicodeEncodeError: 'charmap' codec can't encode character '\U0001f011' in position 81: character maps to <undefined>
2019-02-07 14:32:01: End the game...
2019-02-07 14:32:01:     Game was ended unexpected
2019-02-07 14:32:01: 
